<?xml version="1.0"?>
<robot name="macroed" xmlns:xacro="http://ros.org/wiki/xacro">

<xacro:property name="length" value='0.45' />
<xacro:property name="width"  value='0.4' />
<xacro:property name='height' value='0.17' />
<xacro:property name="wheel_radius" value='0.05' />
<xacro:property name="wheel_width" value='0.03' />
<xacro:property name="sheet_length" value='0.07' />
<xacro:property name="sheet_width" value='0.07' />
<xacro:property name="sheet_height" value='0.01' />
<xacro:property name="c_radius" value='0.01'/>
<xacro:property name="c_height" value='0.05'/>
<xacro:property name="cylin_radius" value='0.07' />
<xacro:property name="cylin_height" value='0.04' />
<xacro:property name="rod_radius" value='0.018' />
<xacro:property name="rod_length" value='0.3'/>


<material name="blue">
    <color rgba="0.1 0.0 0.9 1"/>
</material>
<material name="grey">
    <color rgba="0.191 0.191 0.191 1"/>
</material>

<xacro:macro name="default_inertial" params="mass">
    <inertial>
      <mass value="${mass}" />
      <inertia ixx="1.0" ixy="0.0" ixz="0.0" iyy="1.0" iyz="0.0" izz="1.0" />
    </inertial>
  </xacro:macro>

<link name="base_link">
    <visual>
        <geometry>
           <box size="${length} ${width} ${height}"/>
        </geometry>
        <material name='blue'/> 
    </visual>
    <collision>
        <geometry>
            <box size= "${length} ${width} ${height}"/>
        </geometry>
    </collision>
    <inertial>
        <mass value="5"/>
       <inertia ixx="0.07871" ixy="0" ixz="0" iyy="0.09642" iyz="0.0" izz="0.1510"/>
    </inertial>
</link>

<xacro:macro name="sheets" params="prefix suffix reflectx reflecty">
    <link name="${prefix}_${suffix}_sheet">
        <visual>
            <geometry>
                <box size="${sheet_length} ${sheet_width} ${sheet_height}"/>
            </geometry>
        </visual>
        <collision>
            <geometry>
                <box size="${sheet_length} ${sheet_width} ${sheet_height}"/>
            </geometry>
        </collision>
        <inertial>
            <mass value="0.01"/>
            <inertia ixx="0.000004167" ixy="0.0" ixz="0.0" iyy="0.000004167" iyz="0.0" izz="0.000008167"/>
        </inertial>
        
    </link>
    <joint name="${prefix}_${suffix}_sheet_joint" type="fixed">
        <parent link="base_link"/>
        <child link="${prefix}_${suffix}_sheet"/>
        <origin xyz="${(length-sheet_length)*0.5*reflectx} ${(width-sheet_width)*0.5*reflecty} -0.085" rpy="0.0 0.0 0.0"/>
    </joint>

    <link name="${prefix}_${suffix}_scylinder">
        <visual>
            <geometry>
                <cylinder radius="${c_radius}" length="${c_height}"/>
            </geometry>
        </visual>
        <collision>
                <geometry>
                    <cylinder radius="${c_radius}" length="${c_height}"/>
                </geometry>
        </collision>
        <inertial>
            <mass value="0.01"/>
           <inertia ixx="0.0000023333" ixy="0.0" ixz="0.0" iyy="0.0000023333" iyz="0.0" izz="0.0000005"/>
        </inertial>
    </link>
    <joint name="${prefix}_${suffix}_sheet_cylinder" type="fixed">
        <parent link="${prefix}_${suffix}_sheet"/>
        <child link="${prefix}_${suffix}_scylinder"/>
    </joint>

    <link name="${prefix}_${suffix}_wheel">
        <visual>
            <geometry>
                <cylinder radius="${wheel_radius}" length="${wheel_width}"/>
            </geometry>
        </visual>
        <collision>
                <geometry>
                    <cylinder radius="${wheel_radius}" length="${wheel_width}"/>
                </geometry>
        </collision>
        <inertial>
            <mass value="1"/>
           <inertia ixx="0.0007" ixy="0.0" ixz="0.0" iyy="0.0007" iyz="0.0" izz="0.00125"/>
        </inertial>
    </link>
    <joint name="${prefix}_${suffix}_scylinder_wheel" type="continuous">
        <axis xyz="0 0.0 1.0"/>
        <parent link="${prefix}_${suffix}_scylinder"/>
        <child link="${prefix}_${suffix}_wheel"/>
        <origin xyz="0.0 0.0 -0.07" rpy="1.57 0.0 0.0"/>
    </joint>
    <gazebo reference="${prefix}_${suffix}_wheel">
      <mu1 value="200.0"/>
      <mu2 value="100.0"/>
      <kp value="10000000.0" />
      <kd value="1.0" />
      <material>Gazebo/Grey</material>
    </gazebo>
    <transmission name="${prefix}_${suffix}_wheel_trans">
      <type>transmission_interface/SimpleTransmission</type>
      <actuator name="${prefix}_${suffix}_wheel_motor">
        <mechanicalReduction>1</mechanicalReduction>
      </actuator>
      <joint name="${prefix}_${suffix}_scylinder_wheel">
        <hardwareInterface>VelocityJointInterface</hardwareInterface>
      </joint>
    </transmission>
</xacro:macro>
<xacro:sheets prefix="left" suffix="front" reflectx="1" reflecty="-1" />
<xacro:sheets prefix="left" suffix="back" reflectx="-1" reflecty="-1"/>
 <xacro:sheets prefix="right" suffix="back" reflectx="-1" reflecty="1" />
<xacro:sheets prefix="right" suffix="front" reflectx="1" reflecty="1" />  

<link name="rod">
<visual>
<geometry>
    <cylinder radius="${rod_radius}" length="${rod_length}"/>
</geometry>
<origin xyz="0.0 0.0 0.17"/>
</visual>
<collision>
    <geometry>
    <cylinder radius="${rod_radius}" length="${rod_length}"/>
    </geometry>
</collision>
<inertial>
    <mass value="1.75"/>
   <inertia ixx="0.007581" ixy="0.0" ixz="0.0" iyy="0.007581" iyz="0.0" izz="0.000162"/>
</inertial>
</link>

<joint name="base_to_rod" type="fixed">
    <parent link="base_link"/>
    <child link="rod"/>
</joint>

<link name="cylin">
    <visual>
        <geometry>
            <cylinder radius="${cylin_radius}" length="${cylin_height}"/>
        </geometry>
        <material name='grey'/>
    </visual>
    <collision>
        <geometry>
            <cylinder radius="${cylin_radius}" length="${cylin_height}"/>
        </geometry>
    </collision>
  <inertial>
      <mass value="0.65"/>
     <inertia ixx="0.000883" ixy="0.0" ixz="0.0" iyy="0.000883" iyz="0.0" izz="0.0015925"/>
  </inertial>
</link>
<joint name="rod_cylin" type="continuous">
    <axis xyz="0.0 0.0 1"/>
    <parent link="rod"/>
    <child link="cylin"/>
    <origin xyz="0.0 0.0 0.32"/>
</joint>

<transmission name="cylin_trans">
    <type>transmission_interface/SimpleTransmission</type>
    <actuator name="$cylin_motor">
      <mechanicalReduction>1</mechanicalReduction>
    </actuator>
    <joint name="rod_cylin">
      <hardwareInterface>PositionJointInterface</hardwareInterface>
    </joint>
</transmission>

<gazebo>
    <plugin name="gazebo_ros_control" filename="libgazebo_ros_control.so">
      <robotNamespace>/</robotNamespace>
    </plugin>
</gazebo>
</robot>
